Workbook

Sheet Disprz
D3: Stage
B4: Region | C4: Timeline | D4: Won | E4: Contracting ($) | F4: Negotiation ($) | G4: Proposal ($) | H4: SQO ($) | I4: Demos (Deals)
B5: Disprz (All regions) | C5: Q1 | D5: =D10+D15+D20+D25 -> 835000 | E5: =E10+E15+E20+E25 -> 928842.84 | F5: =F10+F15+F20+F25 -> 1350324.6 | G5: =G10+G15+G20+G25 -> 2859227.4 | H5: =H10+H15+H20+H25 -> 4860067.7 | I5: =I10+I15+I20+I25 -> 596.92991
C6: Q2 | D6: =D11+D16+D21+D26 -> 905000 | E6: =E11+E16+E21+E26 -> 1010285.9 | F6: =F11+F16+F21+F26 -> 1458063.2 | G6: =G11+G16+G21+G26 -> 3100182.8 | H6: =H11+H16+H21+H26 -> 5322187.4 | I6: =I11+I16+I21+I26 -> 652.02102
C7: Q3 | D7: =D12+D17+D22+D27 -> 985000 | E7: =E12+E17+E22+E27 -> 1094789.4 | F7: =F12+F17+F22+F27 -> 1614889.1 | G7: =G12+G17+G22+G27 -> 3438437.6 | H7: =H12+H17+H22+H27 -> 5847158.3 | I7: =I12+I17+I22+I27 -> 715.58646
C8: Q4 | D8: =D13+D18+D23+D28 -> 1075000 | E8: =E13+E18+E23+E28 -> 1210053.5 | F8: =F13+F18+F23+F28 -> 1772570.4 | G8: =G13+G18+G23+G28 -> 3799799.1 | H8: =H13+H18+H23+H28 -> 6517136.6 | I8: =I13+I18+I23+I28 -> 789.05454
C9: FY25-26 | D9: =D14+D19+D24+D29 -> 3800000 | E9: =E14+E19+E24+E29 -> 4243971.7 | F9: =F14+F19+F24+F29 -> 6195847.2 | G9: =G14+G19+G24+G29 -> 13197647 | H9: =H14+H19+H24+H29 -> 22546550 | I9: =I14+I19+I24+I29 -> 2753.5919
B10: IND | C10: Q1 | D10: 375000 | E10: 417087 | F10: 558056 | G10: 1146503 | H10: 1957068 | I10: 239
C11: Q2 | D11: 375000 | E11: 417087 | F11: 558056 | G11: 1146503 | H11: 1957068 | I11: 239
C12: Q3 | D12: 375000 | E12: 417087 | F12: 558056 | G12: 1146503 | H12: 1957068 | I12: 239
C13: Q4 | D13: 375000 | E13: 417087 | F13: 558056 | G13: 1146503 | H13: 1957068 | I13: 239
C14: FY25-26 | D14: =SUM(D10:D13) -> 1500000 | E14: =SUM(E10:E13) -> 1668348 | F14: =SUM(F10:F13) -> 2232224 | G14: =SUM(G10:G13) -> 4586012 | H14: =SUM(H10:H13) -> 7828272 | I14: =SUM(I10:I13) -> 956
B15: SEA | C15: Q1 | D15: 250000 | E15: =SEA!I75 -> 284210 | F15: =SEA!I76 -> 509511 | G15: =SEA!I77 -> 1030409 | H15: =SEA!I78 -> 1382954 | I15: =SEA!I70 -> 213
C16: Q2 | D16: 275000 | E16: =SEA!I92 -> 316555 | F16: =SEA!I93 -> 556582 | G16: =SEA!I94 -> 1127960 | H16: =SEA!I95 -> 1525349 | I16: =SEA!I87 -> 238
C17: Q3 | D17: 325000 | E17: =SEA!I110 -> 369905 | F17: =SEA!I111 -> 673321 | G17: =SEA!I112 -> 1357517 | H17: =SEA!I113 -> 1809173 | I17: =SEA!I105 -> 277
C18: Q4 | D18: 350000 | E18: =SEA!I128 -> 415302 | F18: =SEA!I129 -> 743610 | G18: =SEA!I130 -> 1503009 | H18: =SEA!I131 -> 1998662 | I18: =SEA!I123 -> 304
C19: FY25-26 | D19: =SUM(D15:D18) -> 1200000 | E19: =SUM(E15:E18) -> 1385972 | F19: =SUM(F15:F18) -> 2483024 | G19: =SUM(G15:G18) -> 5018895 | H19: =SUM(H15:H18) -> 6716138 | I19: =SUM(I15:I18) -> 1032
B20: KSA | C20: Q1 | D20: 100000 | E20: =KSA!K43 -> 113316.29 | F20: =KSA!K44 -> 135772.32 | G20: =KSA!K45 -> 283757.05 | H20: =KSA!K46 -> 635840.52 | I20: =KSA!K55 -> 54.856616
C21: Q2 | D21: 125000 | E21: =KSA!K61 -> 141645.37 | F21: =KSA!K62 -> 169715.4 | G21: =KSA!K63 -> 354696.31 | H21: =KSA!K64 -> 794800.66 | I21: =KSA!K73 -> 68.57077
C22: Q3 | D22: 125000 | E22: =KSA!K78 -> 141645.37 | F22: =KSA!K79 -> 169715.4 | G22: =KSA!K80 -> 354696.31 | H22: =KSA!K81 -> 794800.66 | I22: =KSA!K90 -> 68.57077
C23: Q4 | D23: 150000 | E23: =KSA!K95 -> 169974.44 | F23: =KSA!K96 -> 203658.48 | G23: =KSA!K97 -> 425635.57 | H23: =KSA!K98 -> 953760.79 | I23: =KSA!K107 -> 82.284923
C24: FY25-26 | D24: =SUM(D20:D23) -> 500000 | E24: =SUM(E20:E23) -> 566581.47 | F24: =SUM(F20:F23) -> 678861.6 | G24: =SUM(G20:G23) -> 1418785.2 | H24: =SUM(H20:H23) -> 3179202.6 | I24: =SUM(I20:I23) -> 274.28308
B25: RoME | C25: Q1 | D25: 110000 | E25: =RoME!I43 -> 114229.55 | F25: =RoME!I44 -> 146985.23 | G25: =RoME!I45 -> 398558.35 | H25: =RoME!I46 -> 884205.21 | I25: =RoME!I55 -> 90.07329
C26: Q2 | D26: 130000 | E26: =RoME!I61 -> 134998.56 | F26: =RoME!I62 -> 173709.82 | G26: =RoME!I63 -> 471023.51 | H26: =RoME!I64 -> 1044969.8 | I26: =RoME!I73 -> 106.45025
C27: Q3 | D27: 160000 | E27: =RoME!I78 -> 166152.07 | F27: =RoME!I79 -> 213796.7 | G27: =RoME!I80 -> 579721.24 | H27: =RoME!I81 -> 1286116.7 | I27: =RoME!I90 -> 131.01569
C28: Q4 | D28: 200000 | E28: =RoME!I95 -> 207690.09 | F28: =RoME!I96 -> 267245.88 | G28: =RoME!I97 -> 724651.55 | H28: =RoME!I98 -> 1607645.8 | I28: =RoME!I107 -> 163.76962
C29: FY25-26 | D29: =SUM(D25:D28) -> 600000 | E29: =SUM(E25:E28) -> 623070.27 | F29: =SUM(F25:F28) -> 801737.63 | G29: =SUM(G25:G28) -> 2173954.7 | H29: =SUM(H25:H28) -> 4822937.5 | I29: =SUM(I25:I28) -> 491.30886

Sheet IND
D1: IND AOP
C4: Conversion % | D4: Stage | E4: Sales | F4: Marketing | G4: Partnership | H4: Farming | I4: Outbound
D5: Demo to SQO | E5: 0.7 | F5: 0.4 | G5: 0.5154 | H5: 0.96 | I5: 0.37
D6: SQO to Proposal | E6: 0.7966 | F6: 0.6 | G6: 0.597 | H6: 1 | I6: 0.4303 | J6: =F6*F7*F8*F9 -> 0.1833
D7: Proposal to Nego | E7: 0.4681 | F7: 0.47 | G7: 0.55 | H7: 0.863 | I7: 0.34
D8: Nego to Contracting | E8: 0.64 | F8: 0.65 | G8: 0.8182 | H8: 0.9841 | I8: 0.65
D9: Contracting to Won | E9: 1 | F9: 1 | G9: 0.6667 | H9: 0.9355 | I9: 0.95
D10: Demo to Won | E10: =E5*E6*E7*E8*E9 -> 0.16705403 | F10: =F5*F6*F7*F8*F9 -> 0.07332 | G10: =G5*G6*G7*G8*G9 -> 0.092314807 | H10: =H5*H6*H7*H8*H9 -> 0.76271986 | I10: =I5*I6*I7*I8*I9 -> 0.033426349 | J10: =I7*I8*I9 -> 0.20995
D11: FY25-26
D13: Targets | E13: Sales | F13: Marketing | G13: Partnership | H13: Farming | I13: Outbound | J13: Total
A14: Note - 100k content target for Partnerships is outside this | D14: FY25-26 | E14: 310000 | F14: 240000 | G14: 250000 | H14: 400000 | I14: 300000 | J14: =SUM(E14:I14) -> 1500000
D15: ACV | E15: 19500 | F15: 19400 | G15: 20700 | H15: 8400 | I15: 18000
D17: FY25-26 | E17: Sales | F17: Marketing | G17: Partnership | H17: Farming | I17: Outbound | J17: Total
C18: No. of deals | D18: Won | E18: =E14/E15 -> 15.897436 | F18: =F14/F15 -> 12.371134 | G18: =G14/G15 -> 12.077295 | H18: =H14/H15 -> 47.619048 | I18: =I14/I15 -> 16.666667 | J18: =SUM(E18:I18) -> 104.63158
D19: Contracting | E19: =E28/E15 -> 15.897436 | F19: =F28/F15 -> 12.371134 | G19: =G28/G15 -> 18.115036 | H19: =H28/H15 -> 50.902242 | I19: =I28/I15 -> 17.54386 | J19: =SUM(E19:I19) -> 114.82971
D20: Negotiation | E20: =E29/E15 -> 24.839744 | F20: =F29/F15 -> 19.032514 | G20: =G29/G15 -> 22.140108 | H20: =H29/H15 -> 51.724664 | I20: =I29/I15 -> 26.990553 | J20: =SUM(E20:I20) -> 144.72758
D21: Proposal | E21: =E30/E15 -> 53.065037 | F21: =F30/F15 -> 40.49471 | G21: =G30/G15 -> 40.254742 | H21: =H30/H15 -> 59.93588 | I21: =I30/I15 -> 79.38398 | J21: =SUM(E21:I21) -> 273.13435
D22: SQO | E22: =E31/E15 -> 66.614407 | F22: =F31/F15 -> 67.491184 | G22: =G31/G15 -> 67.428378 | H22: =H31/H15 -> 59.93588 | I22: =I31/I15 -> 184.4852 | J22: =SUM(E22:I22) -> 445.95505
B23: =230/1300 -> 0.17692308 | D23: Demo | E23: =E22/E5 -> 95.163438 | F23: =F22/F5 -> 168.72796 | G23: =G22/G5 -> 130.82728 | H23: =H22/H5 -> 62.433208 | I23: =I22/I5 -> 498.60864 | J23: =SUM(E23:I23) -> 955.76052
B25: =18%*500 -> 90
D26: FY25-26 | E26: Sales | F26: Marketing | G26: Partnership | H26: Farming | I26: Outbound | J26: Total
C27: Gross ARR | D27: Won | E27: =E14 -> 310000 | F27: =F14 -> 240000 | G27: =G14 -> 250000 | H27: =H14 -> 400000 | I27: =I14 -> 300000 | J27: =SUM(E27:I27) -> 1500000
D28: Contracting | E28: =E14/E9 -> 310000 | F28: =F14/F9 -> 240000 | G28: =G14/G9 -> 374981.25 | H28: =H14/H9 -> 427578.83 | I28: =I14/I9 -> 315789.47 | J28: =SUM(E28:I28) -> 1668349.6
D29: Negotiation | E29: =E28/E8 -> 484375 | F29: =F28/F8 -> 369230.77 | G29: =G28/G8 -> 458300.23 | H29: =H28/H8 -> 434487.18 | I29: =I28/I8 -> 485829.96 | J29: =SUM(E29:I29) -> 2232223.1
D30: Proposal | E30: =E29/E7 -> 1034768.2 | F30: =F29/F7 -> 785597.38 | G30: =G29/G7 -> 833273.15 | H30: =H29/H7 -> 503461.39 | I30: =I29/I7 -> 1428911.6 | J30: =SUM(E30:I30) -> 4586011.8
D31: SQO | E31: =E30/E6 -> 1298980.9 | F31: =F30/F6 -> 1309329 | G31: =G30/G6 -> 1395767.4 | H31: =H30/H6 -> 503461.39 | I31: =I30/I6 -> 3320733.5 | J31: =SUM(E31:I31) -> 7828272.3
D36: Quarter splits
C38: Gross ARR | D38: Q1 | E38: Sales | F38: Marketing | G38: Partnership | H38: Farming | I38: Outbound | J38: Total
D39: Won | E39: =E14/4 -> 77500 | F39: =F14/4 -> 60000 | G39: =G14/4 -> 62500 | H39: =H14/4 -> 100000 | I39: =I14/4 -> 75000 | J39: =SUM(E39:I39) -> 375000
D40: Contracting | E40: =E39/E9 -> 77500 | F40: =F39/F9 -> 60000 | G40: =G39/G9 -> 93745.313 | H40: =H39/H9 -> 106894.71 | I40: =I39/I9 -> 78947.368 | J40: =SUM(E40:I40) -> 417087.39
D41: Negotiation | E41: =E40/E8 -> 121093.75 | F41: =F40/F8 -> 92307.692 | G41: =G40/G8 -> 114575.06 | H41: =H40/H8 -> 108621.8 | I41: =I40/I8 -> 121457.49 | J41: =SUM(E41:I41) -> 558055.79
D42: Proposal | E42: =E41/E7 -> 258692.05 | F42: =F41/F7 -> 196399.35 | G42: =G41/G7 -> 208318.29 | H42: =H41/H7 -> 125865.35 | I42: =I41/I7 -> 357227.91 | J42: =SUM(E42:I42) -> 1146502.9
D43: SQO | E43: =E42/E6 -> 324745.23 | F43: =F42/F6 -> 327332.24 | G43: =G42/G6 -> 348941.86 | H43: =H42/H6 -> 125865.35 | I43: =I42/I6 -> 830183.39 | J43: =SUM(E43:I43) -> 1957068.1
C46: No. of deals | D46: Q1 | E46: Sales | F46: Marketing | G46: Partnership | H46: Farming | I46: Outbound | J46: Total
D47: Won | E47: =E39/$E$15 -> 3.974359 | F47: =F39/$F$15 -> 3.0927835 | G47: =G39/$G$15 -> 3.0193237 | H47: =H39/$H$15 -> 11.904762 | I47: =I39/$I$15 -> 4.1666667 | J47: =SUM(E47:I47) -> 26.157895
D48: Contracting | E48: =E40/$E$15 -> 3.974359 | F48: =F40/$F$15 -> 3.0927835 | G48: =G40/$G$15 -> 4.5287591 | H48: =H40/$H$15 -> 12.725561 | I48: =I40/$I$15 -> 4.3859649 | J48: =SUM(E48:I48) -> 28.707427
D49: Negotiation | E49: =E41/$E$15 -> 6.2099359 | F49: =F41/$F$15 -> 4.7581285 | G49: =G41/$G$15 -> 5.535027 | H49: =H41/$H$15 -> 12.931166 | I49: =I41/$I$15 -> 6.7476383 | J49: =SUM(E49:I49) -> 36.181896
D50: Proposal | E50: =E42/$E$15 -> 13.266259 | F50: =F42/$F$15 -> 10.123678 | G50: =G42/$G$15 -> 10.063685 | H50: =H42/$H$15 -> 14.98397 | I50: =I42/$I$15 -> 19.845995 | J50: =SUM(E50:I50) -> 68.283587
D51: SQO | E51: =E43/$E$15 -> 16.653602 | F51: =F43/$F$15 -> 16.872796 | G51: =G43/$G$15 -> 16.857094 | H51: =H43/$H$15 -> 14.98397 | I51: =I43/$I$15 -> 46.121299 | J51: =SUM(E51:I51) -> 111.48876
D52: Demo | E52: =E51/E5 -> 23.79086 | F52: =F51/F5 -> 42.18199 | G52: =G51/G5 -> 32.706819 | H52: =H51/H5 -> 15.608302 | I52: =I51/I5 -> 124.65216 | J52: =SUM(E52:I52) -> 238.94013
...

Sheet SEA
C1: SEA AOP
C2: SEA Total | D2: Final Closures (Won)
D3: AMJ'25 | E3: JAS'25 | F3: OND'25 | G3: JFM'26 | H3: FY'25-26
C4: Sales | D4: 45000 | E4: 60000 | F4: 60000 | G4: 60000 | H4: 225000 | I4: 0.19
C5: Outbound/ BDR | D5: 65000 | E5: 65000 | F5: 85000 | G5: 85000 | H5: 300000 | I5: 0.25
C6: Marketing | D6: 50000 | E6: 55000 | F6: 55000 | G6: 65000 | H6: 225000 | I6: 0.19 | K6: =E6/28% -> 196428.57
C7: Farming | D7: 45000 | E7: 50000 | F7: 60000 | G7: 70000 | H7: 225000 | I7: 0.19
C8: Partnership | D8: 45000 | E8: 45000 | F8: 65000 | G8: 70000 | H8: 225000 | I8: 0.19
D9: 250000 | E9: 275000 | F9: 325000 | G9: 350000 | H9: 1200000 | I9: 1
C11: SE Asia 2025 - 26 PLAN
C12: MY + SG | D12: Final Closures (Won)
D13: AMJ'25 | E13: JAS'25 | F13: OND'25 | G13: JFM'26 | H13: FY'25-26
C14: Sales | D14: 10000 | E14: 15000 | F14: 15000 | G14: 20000 | H14: 60000 | I14: 0.17
C15: Outbound / BDR | D15: 25000 | E15: 25000 | F15: 25000 | G15: 25000 | H15: 100000 | I15: 0.29
C16: Marketing | D16: 15000 | E16: 15000 | F16: 15000 | G16: 20000 | H16: 65000 | I16: 0.19
C17: Farming | D17: 15000 | E17: 15000 | F17: 20000 | G17: 25000 | H17: 75000 | I17: 0.21
C18: Partnership | D18: 10000 | E18: 10000 | F18: 15000 | G18: 15000 | H18: 50000 | I18: 0.14
D19: 75000 | E19: 80000 | F19: 90000 | G19: 105000 | H19: 350000 | I19: 1
C22: Indonesia | D22: Final Closures (Won)
D23: AMJ'25 | E23: JAS'25 | F23: OND'25 | G23: JFM'26 | H23: FY'25-26
C24: Sales | D24: 25000 | E24: 30000 | F24: 30000 | G24: 30000 | H24: 115000 | I24: 0.26
C25: Outbound / BDR | D25: 20000 | E25: 20000 | F25: 30000 | G25: 30000 | H25: 100000 | I25: 0.29
C26: Marketing | D26: 25000 | E26: 25000 | F26: 25000 | G26: 25000 | H26: 100000 | I26: 0.22
C27: Farming | D27: 15000 | E27: 20000 | F27: 25000 | G27: 25000 | H27: 85000 | I27: 0.19
C28: Partnership | D28: 10000 | E28: 10000 | F28: 15000 | G28: 15000 | H28: 50000 | I28: 0.11
D29: 95000 | E29: 105000 | F29: 125000 | G29: 125000 | H29: 450000 | I29: 1
C32: Philippines | D32: Final Closures (Won)
D33: AMJ'25 | E33: JAS'25 | F33: OND'25 | G33: JFM'26 | H33: FY'25-26
C34: Sales | D34: 10000 | E34: 15000 | F34: 15000 | G34: 10000 | H34: 50000 | I34: 0.13
C35: Outbound / BDR | D35: 20000 | E35: 20000 | F35: 30000 | G35: 30000 | H35: 100000 | I35: 0.25
C36: Marketing | D36: 10000 | E36: 15000 | F36: 15000 | G36: 20000 | H36: 60000 | I36: 0.15
C37: Farming | D37: 15000 | E37: 15000 | F37: 15000 | G37: 20000 | H37: 65000 | I37: 0.16
C38: Partnership | D38: 25000 | E38: 25000 | F38: 35000 | G38: 40000 | H38: 125000 | I38: 0.31
D39: 80000 | E39: 90000 | F39: 110000 | G39: 120000 | H39: 400000 | I39: 1
C42: FY25-26
B44: No. of deals | C44: FY25-26 | D44: Sales | E44: Marketing | F44: Partnership | G44: Farming | H44: Outbound | I44: Total
C45: Won | D45: 20 | E45: 19 | F45: 14 | G45: 36 | H45: 23 | I45: 111
C46: Contracting | D46: 24 | E46: 21 | F46: 17 | G46: 40 | H46: 25 | I46: 127
C47: Negotiation | D47: 37 | E47: 33 | F47: 41 | G47: 40 | H47: 57 | I47: 208
C48: Proposal | D48: 74 | E48: 64 | F48: 76 | G48: 44 | H48: 144 | I48: 401
...

Sheet KSA
F1: KSA AOP
F3: Quarter targets | G3: Q1 | H3: Q2 | I3: Q3 | J3: Q4 | K3: Total
F4: Gross ARR | G4: 100000 | H4: 125000 | I4: 125000 | J4: 150000 | K4: =SUM(G4:J4) -> 500000
M6: Sales + Outbound | N6: Marketing | O6: Partnership | P6: Farming
C7: 225000 | D7: Outbound + Marketing | F7: Conversion % | G7: Outbound + Marketing | H7: - | I7: Partnership | J7: Farming | M7: 350000 | N7: 100000 | O7: 300000 | P7: 250000
D8: =(G8+H8)/2 -> 0.545 | F8: Demo to SQO | G8: 0.49 | H8: 0.6 | I8: 0.9 | J8: 0.75 | M8: 0.7 | N8: 0.7 | O8: 0.7 | P8: 0.7
D9: =(G9+H9)/2 -> 0.375 | F9: SQO to Proposal | G9: 0.35 | H9: 0.4 | I9: 0.83 | J9: 1 | M9: =M7*M8 -> 245000 | N9: =N7*N8 -> 70000 | O9: =O7*O8 -> 210000 | P9: =P7*P8 -> 175000
D10: =(G10+H10)/2 -> 0.3925 | F10: Proposal to Nego | G10: 0.385 | H10: 0.4 | I10: 0.7 | J10: 0.6
D11: =(G11+H11)/2 -> 0.78935 | F11: Nego to Contracting | G11: 0.7387 | H11: 0.84 | I11: 0.8889 | J11: 1 | M11: =G4/K4 -> 0.2
D12: =(G12+H12)/2 -> 0.84 | F12: Contracting to Won | G12: 0.86 | H12: 0.82 | I12: 0.95 | J12: 0.85 | M12: =H4/K4 -> 0.25
D13: =(G13+H13)/2 -> 0.054035441 | F13: Demo to Won | G13: =G8*G9*G10*G11*G12 -> 0.041946082 | H13: =H8*H9*H10*H11*H12 -> 0.0661248 | I13: =I8*I9*I10*I11*I12 -> 0.44156552 | J13: =J8*J9*J10*J11*J12 -> 0.3825 | M13: =I4/K4 -> 0.25
F14: FY25-26 | L14: 0.3 | M14: =J4/K4 -> 0.3 | O14: 122
C15: =C7*M11 -> 45000 | L15: 0.28 | O15: 150
C16: =C7*M12 -> 56250 | F16: Channel Targets | G16: Outbound + Marketing | H16: - | I16: Partnership | J16: Farming | K16: Total | L16: 0.25 | O16: 50
C17: =C7*M13 -> 56250 | F17: FY25-26 | G17: 225000 | H17: 0 | I17: 150000 | J17: 125000 | K17: =SUM(G17:J17) -> 500000 | L17: 0.17 | O17: =SUM(O14:O16) -> 322
C18: =C7*M14 -> 67500 | F18: ACV | G18: 25000 | H18: 25000 | I18: 18000 | J18: 8000 | K18: =K17/K21 -> 15170.67
F20: FY25-26 | G20: Outbound + Marketing | H20: - | I20: Partnership | J20: Farming | K20: Total | L20: =(G17+H17)/K17 -> 0.45 | N20: Farming | O20: 30
E21: No. of deals | F21: Won | G21: =G17/G18 -> 9 | H21: =H17/H18 -> 0 | I21: =I17/I18 -> 8.3333333 | J21: =J17/J18 -> 15.625 | K21: =SUM(G21:J21) -> 32.958333 | N21: Marketing | O21: =55+55+12 -> 122
F22: Contracting | G22: =G31/G18 -> 10.465116 | H22: =H31/H18 -> 0 | I22: =I31/I18 -> 8.7719298 | J22: =J31/J18 -> 18.382353 | K22: =SUM(G22:J22) -> 37.619399 | N22: Partnership | O22: =66+50+53 -> 169
F23: Negotiation | G23: =G32/G18 -> 14.166937 | H23: =H32/H18 -> 0 | I23: =I32/I18 -> 9.8682977 | J23: =J32/J18 -> 18.382353 | K23: =SUM(G23:J23) -> 42.417588 | O23: =SUM(O20:O22) -> 321
F24: Proposal | G24: =G33/G18 -> 36.797239 | H24: =H33/H18 -> 0 | I24: =I33/I18 -> 14.097568 | J24: =J33/J18 -> 30.637255 | K24: =SUM(G24:J24) -> 81.532062
F25: SQO | G25: =G34/G18 -> 105.13497 | H25: =H34/H18 -> 0 | I25: =I34/I18 -> 16.985022 | J25: =J34/J18 -> 30.637255 | K25: =SUM(G25:J25) -> 152.75724 | N25: Marketing | O25: 100000 | P25: =O25/2+O25/2*20% -> 60000
F26: Demo | G26: =G25/G8 -> 214.56116 | H26: =H25/H8 -> 0 | I26: =I25/I8 -> 18.872247 | J26: =J25/J8 -> 40.849673 | K26: =SUM(G26:J26) -> 274.28308 | N26: Partnership | O26: 300000 | P26: =O26/2+O26/2*20% -> 180000
N27: Farming | O27: 300000 | P27: =O27/2+O27/2*20% -> 180000
N28: Sales + Outbound | O28: 300000 | P28: =O28/2+O28/2*20% -> 180000
F29: FY25-26 | G29: Outbound + Marketing | H29: - | I29: Partnership | J29: Farming | K29: Total | O29: =SUM(O25:O28) -> 1000000 | P29: =SUM(P25:P28) -> 600000
E30: Gross ARR | F30: Won | G30: =G17 -> 225000 | H30: =H17 -> 0 | I30: =I17 -> 150000 | J30: =J17 -> 125000 | K30: =SUM(G30:J30) -> 500000
F31: Contracting | G31: =G17/G12 -> 261627.91 | H31: =H17/H12 -> 0 | I31: =I17/I12 -> 157894.74 | J31: =J17/J12 -> 147058.82 | K31: =SUM(G31:J31) -> 566581.47
F32: Negotiation | G32: =G31/G11 -> 354173.42 | H32: =H31/H11 -> 0 | I32: =I31/I11 -> 177629.36 | J32: =J31/J11 -> 147058.82 | K32: =SUM(G32:J32) -> 678861.6 | N32: Advance
F33: Proposal | G33: =G32/G10 -> 919930.97 | H33: =H32/H10 -> 0 | I33: =I32/I10 -> 253756.23 | J33: =J32/J10 -> 245098.04 | K33: =SUM(G33:J33) -> 1418785.2 | N33: BME
F34: SQO | G34: =G33/G9 -> 2628374.2 | H34: =H33/H9 -> 0 | I34: =I33/I9 -> 305730.39 | J34: =J33/J9 -> 245098.04 | K34: =SUM(G34:J34) -> 3179202.6 | N34: Ravi
F39: Quarter Splits
D40: 0.35
D41: 0.1 | E41: Gross ARR | F41: Q1 | G41: Outbound + Marketing | H41: - | I41: Partnership | J41: Farming | K41: Total
C42: 100000 | D42: 0.3 | E42: Q1 | F42: Won | G42: 45000 | H42: 0 | I42: =C42*D42 -> 30000 | J42: =C42*D43 -> 25000 | K42: =SUM(G42:J42) -> 100000 | L42: =K46/K42 -> 6.3584052
D43: 0.25 | F43: Contracting | G43: =G42/G12 -> 52325.581 | H43: =H42/H12 -> 0 | I43: =I42/I12 -> 31578.947 | J43: =J42/J12 -> 29411.765 | K43: =SUM(G43:J43) -> 113316.29
F44: Negotiation | G44: =G43/G11 -> 70834.684 | H44: =H43/H11 -> 0 | I44: =I43/I11 -> 35525.872 | J44: =J43/J11 -> 29411.765 | K44: =SUM(G44:J44) -> 135772.32
F45: Proposal | G45: =G44/G10 -> 183986.19 | H45: =H44/H10 -> 0 | I45: =I44/I10 -> 50751.245 | J45: =J44/J10 -> 49019.608 | K45: =SUM(G45:J45) -> 283757.05
F46: SQO | G46: =G45/G9 -> 525674.84 | H46: =H45/H9 -> 0 | I46: =I45/I9 -> 61146.079 | J46: =J45/J9 -> 49019.608 | K46: =SUM(G46:J46) -> 635840.52
E49: No. of deals | F49: Q1 | G49: Outbound + Marketing | H49: - | I49: Partnership | J49: Farming | K49: Total
...

Sheet KSA - Old AOP
A1: D | B1: E | C1: F | D1: G | E1: H | F1: I | G1: O | H1: P | I1: Q | J1: R | K1: S | L1: T | M1: U | N1: V | O1: W | P1: X | Q1: Y | R1: Z
A2: 1 | D2: KSA AOP
A3: 2
A4: 3 | D4: Quarter targets | E4: Q1 | F4: Q2 | G4: Q3 | H4: Q4 | I4: Total
A5: 4 | D5: Gross ARR | E5: 100000 | F5: 125000 | G5: 125000 | H5: 150000 | I5: 500000
A6: 5
A7: 6
A8: 7 | D8: Conversion % | E8: Sales + Outbound | F8: Marketing | G8: Partnership | H8: Farming
A9: 8 | D9: Demo to SQO | E9: 0.38 | F9: 0.6 | G9: 0.9 | H9: 0.75
A10: 9 | D10: SQO to Proposal | E10: 0.39 | F10: 0.4 | G10: 0.83 | H10: 1
A11: 10 | D11: Proposal to Nego | E11: 0.37 | F11: 0.4 | G11: 0.7 | H11: 0.6
A12: 11 | D12: Nego to Contracting | E12: 0.64 | F12: 0.84 | G12: 0.89 | H12: 1
A13: 12 | D13: Contracting to Won | E13: 0.9 | F13: 0.82 | G13: 0.95 | H13: 0.85
A14: 13 | D14: Demo to Won | E14: 0.03 | F14: 0.07 | G14: 0.44 | H14: 0.38
A15: 14 | D15: FY25-26
A16: 15
A17: 16 | D17: Channel Targets | E17: Sales + Outbound | F17: Marketing | G17: Partnership | H17: Farming | I17: Total
A18: 17 | D18: FY25-26 | E18: 135000 | F18: 90000 | G18: 150000 | H18: 125000 | I18: 500000
A19: 18 | D19: ACV | E19: 25000 | F19: 25000 | G19: 18000 | H19: 8000 | I19: 15171
A20: 19
A21: 20 | D21: FY25-26 | E21: Sales + Outbound | F21: Marketing | G21: Partnership | H21: Farming | I21: Total
A22: 21 | C22: No. of deals | D22: Won | E22: 5 | F22: 4 | G22: 8 | H22: 16 | I22: 33
A23: 22 | D23: Contracting | E23: 6 | F23: 4 | G23: 9 | H23: 18 | I23: 38
A24: 23 | D24: Negotiation | E24: 9 | F24: 5 | G24: 10 | H24: 18 | I24: 43
A25: 24 | D25: Proposal | E25: 25 | F25: 13 | G25: 14 | H25: 31 | I25: 83
A26: 25 | D26: SQO | E26: 66 | F26: 33 | G26: 17 | H26: 31 | I26: 146
A27: 26 | D27: Demo | E27: 172 | F27: 54 | G27: 19 | H27: 41 | I27: 287
A28: 27
A29: 28
A30: 29 | D30: FY25-26 | E30: Sales + Outbound | F30: Marketing | G30: Partnership | H30: Farming | I30: Total
A31: 30 | C31: Gross ARR | D31: Won | E31: 135000 | F31: 90000 | G31: 150000 | H31: 125000 | I31: 500000
A32: 31 | D32: Contracting | E32: 150000 | F32: 109756 | G32: 157895 | H32: 147059 | I32: 564710
A33: 32 | D33: Negotiation | E33: 235331 | F33: 130662 | G33: 177629 | H33: 147059 | I33: 690681
A34: 33 | D34: Proposal | E34: 636030 | F34: 326655 | G34: 253756 | H34: 245098 | I34: 1461539
A35: 34 | D35: SQO | E35: 1637986 | F35: 816638 | G35: 305730 | H35: 245098 | I35: 3005452
A36: 35
A37: 36
A38: 37
A39: 38
A40: 39 | D40: Quarter Splits
...

Sheet RoME
D1: RoME AOP
D3: Quarter targets | E3: Q1 | F3: Q2 | G3: Q3 | H3: Q4 | I3: Total
D4: Gross ARR | E4: 110000 | F4: 130000 | G4: 160000 | H4: 200000 | I4: =SUM(E4:H4) -> 600000
D7: Conversion % | E7: Sales + Outbound | F7: Marketing | G7: Partnership | H7: Farming
D8: Demo to SQO | E8: 0.38 | F8: 0.44 | G8: 0.4 | H8: 0.5
D9: SQO to Proposal | E9: 0.3883 | F9: 0.35 | G9: 0.53 | H9: 1
D10: Proposal to Nego | E10: 0.37 | F10: 0.5 | G10: 0.3 | H10: 0.3077
D11: Nego to Contracting | E11: 0.6374 | F11: 0.7895 | G11: 0.8889 | H11: 1
D12: Contracting to Won | E12: 1 | F12: 0.8667 | G12: 1 | H12: 1
D13: Demo to Won | E13: =E8*E9*E10*E11*E12 -> 0.03479884 | F13: =F8*F9*F10*F11*F12 -> 0.052687993 | G13: =G8*G9*G10*G11*G12 -> 0.05653404 | H13: =H8*H9*H10*H11*H12 -> 0.15385 | I13: =I8*I9*I10*I11*I12 -> 0
D14: FY25-26 | J14: =E17/I17 -> 0.33333333
J15: =F17/I17 -> 0.25
D16: Targets | E16: Sales + Outbound | F16: Marketing | G16: Partnership | H16: Farming | I16: Total | J16: =G17/I17 -> 0.25
D17: FY25-26 | E17: 200000 | F17: 150000 | G17: 150000 | H17: 100000 | I17: =SUM(E17:H17) -> 600000 | J17: =H17/I17 -> 0.16666667 | L17: =F17/4/28% -> 133928.57
D18: ACV | E18: 30000 | F18: 21000 | G18: 32000 | H18: 8000
D20: FY25-26 | E20: Sales + Outbound | F20: Marketing | G20: Partnership | H20: Farming | I20: Total
C21: No. of deals | D21: Won | E21: =E17/E18 -> 6.6666667 | F21: =F17/F18 -> 7.1428571 | G21: =G17/G18 -> 4.6875 | H21: =H17/H18 -> 12.5 | I21: =SUM(E21:H21) -> 30.997024
D22: Contracting | E22: =E31/E18 -> 6.6666667 | F22: =F31/F18 -> 8.2414413 | G22: =G31/G18 -> 4.6875 | H22: =H31/H18 -> 12.5 | I22: =SUM(E22:H22) -> 32.095608
D23: Negotiation | E23: =E32/E18 -> 10.459157 | F23: =F32/F18 -> 10.438811 | G23: =G32/G18 -> 5.2733716 | H23: =H32/H18 -> 12.5 | I23: =SUM(E23:H23) -> 38.67134
D24: Proposal | E24: =E33/E18 -> 28.267992 | F24: =F33/F18 -> 20.877622 | G24: =G33/G18 -> 17.577905 | H24: =H33/H18 -> 40.623984 | I24: =SUM(E24:H24) -> 107.3475
D25: SQO | E25: =E34/E18 -> 72.799361 | F25: =F34/F18 -> 59.650348 | G25: =G34/G18 -> 33.165859 | H25: =H34/H18 -> 40.623984 | I25: =SUM(E25:H25) -> 206.23955
D26: Demo | E26: =E25/E8 -> 191.57727 | F26: =F25/F8 -> 135.56897 | G26: =G25/G8 -> 82.914648 | H26: =H25/H8 -> 81.247969 | I26: =SUM(E26:H26) -> 491.30886
D29: FY25-26 | E29: Sales + Outbound | F29: Marketing | G29: Partnership | H29: Farming | I29: Total
C30: Gross ARR | D30: Won | E30: 200000 | F30: 150000 | G30: 150000 | H30: 100000 | I30: =SUM(E30:H30) -> 600000
D31: Contracting | E31: =E17/E12 -> 200000 | F31: =F17/F12 -> 173070.27 | G31: =G17/G12 -> 150000 | H31: =H17/H12 -> 100000 | I31: =SUM(E31:H31) -> 623070.27
D32: Negotiation | E32: =E31/E11 -> 313774.71 | F32: =F31/F11 -> 219215.03 | G32: =G31/G11 -> 168747.89 | H32: =H31/H11 -> 100000 | I32: =SUM(E32:H32) -> 801737.63
D33: Proposal | E33: =E32/E10 -> 848039.76 | F33: =F32/F10 -> 438430.06 | G33: =G32/G10 -> 562492.97 | H33: =H32/H10 -> 324991.88 | I33: =SUM(E33:H33) -> 2173954.7
D34: SQO | E34: =E33/E9 -> 2183980.8 | F34: =F33/F9 -> 1252657.3 | G34: =G33/G9 -> 1061307.5 | H34: =H33/H9 -> 324991.88 | I34: =SUM(E34:H34) -> 4822937.5
D39: Quarter Splits
B40: 0.33333333
B41: 0.25 | C41: Gross ARR | D41: Q1 | E41: Sales + Outbound | F41: Marketing | G41: Partnership | H41: Farming | I41: Total
A42: 110000 | B42: 0.25 | C42: Q1 | D42: Won | E42: =A42*B40 -> 36666.667 | F42: =A42*B41 -> 27500 | G42: =A42*B42 -> 27500 | H42: =A42*B43 -> 18333.333 | I42: =SUM(E42:H42) -> 110000
B43: 0.16666667 | D43: Contracting | E43: =E42/E12 -> 36666.667 | F43: =F42/F12 -> 31729.549 | G43: =G42/G12 -> 27500 | H43: =H42/H12 -> 18333.333 | I43: =SUM(E43:H43) -> 114229.55
D44: Negotiation | E44: =E43/E11 -> 57525.363 | F44: =F43/F11 -> 40189.422 | G44: =G43/G11 -> 30937.113 | H44: =H43/H11 -> 18333.333 | I44: =SUM(E44:H44) -> 146985.23
D45: Proposal | E45: =E44/E10 -> 155473.96 | F45: =F44/F10 -> 80378.844 | G45: =G44/G10 -> 103123.71 | H45: =H44/H10 -> 59581.844 | I45: =SUM(E45:H45) -> 398558.35
D46: SQO | E46: =E45/E9 -> 400396.49 | F46: =F45/F9 -> 229653.84 | G46: =G45/G9 -> 194573.04 | H46: =H45/H9 -> 59581.844 | I46: =SUM(E46:H46) -> 884205.21
C49: No. of deals | D49: Q1 | E49: Sales + Outbound | F49: Marketing | G49: Partnership | H49: Farming | I49: Total
C50: Q1 | D50: Won | E50: =E42/E18 -> 1.2222222 | F50: =F42/F18 -> 1.3095238 | G50: =G42/G18 -> 0.859375 | H50: =H42/H18 -> 2.2916667 | I50: =SUM(E50:H50) -> 5.6827877
D51: Contracting | E51: =E43/E18 -> 1.2222222 | F51: =F43/F18 -> 1.5109309 | G51: =G43/G18 -> 0.859375 | H51: =H43/H18 -> 2.2916667 | I51: =SUM(E51:H51) -> 5.8841948
D52: Negotiation | E52: =E44/E18 -> 1.9175121 | F52: =F44/F18 -> 1.913782 | G52: =G44/G18 -> 0.96678479 | H52: =H44/H18 -> 2.2916667 | I52: =SUM(E52:H52) -> 7.0897456
...
